#VRML_SIM R2023b utf8

EXTERNPROTO "https://raw.githubusercontent.com/cyberbotics/webots/R2023b/projects/objects/backgrounds/protos/TexturedBackground.proto"
EXTERNPROTO "https://raw.githubusercontent.com/cyberbotics/webots/R2023b/projects/objects/backgrounds/protos/TexturedBackgroundLight.proto"
EXTERNPROTO "https://raw.githubusercontent.com/cyberbotics/webots/R2023b/projects/objects/floors/protos/RectangleArena.proto"

WorldInfo {
}
Viewpoint {
  position -1.8368064860356632 1.1320193963202493e-32 -4.20598375844134e-16
}
TexturedBackground {
}
TexturedBackgroundLight {
}
RectangleArena {
  floorTileSize 0.1 0.1
  wallHeight 0.001
}
Robot {
  translation 0 0 0.08
  children [
    HingeJoint {
      jointParameters HingeJointParameters {
      }
      device [
        RotationalMotor {
        }
      ]
      endPoint DEF support_wheel_1 Solid {
        translation 0.15 -0.25 -0.05
        rotation 0 1 0 1.5707996938995747
        children [
          DEF SUPPORT_WHEEL Shape {
            appearance PBRAppearance {
              baseColor 1 0 0
              metalness 0
            }
            geometry Cylinder {
              height 0.03
              radius 0.025
            }
          }
        ]
        boundingObject USE SUPPORT_WHEEL
        physics Physics {
        }
      }
    }
    HingeJoint {
      jointParameters HingeJointParameters {
      }
      device [
        RotationalMotor {
        }
      ]
      endPoint DEF support_wheel_3 Solid {
        translation -0.15 0.25 -0.05
        rotation 0 1 0 1.5707996938995747
        children [
          USE SUPPORT_WHEEL
        ]
        name "solid(2)"
        boundingObject USE SUPPORT_WHEEL
        physics Physics {
        }
      }
    }
    HingeJoint {
      jointParameters HingeJointParameters {
        anchor 0.27 0 0
      }
      device [
        RotationalMotor {
          name "motor_right"
        }
      ]
      endPoint Solid {
        translation 0.27 0 0
        rotation 0 -0.9999999999999999 0 1.5707953071795862
        children [
          DEF WHEEL Shape {
            appearance PBRAppearance {
              baseColor 1 1 0
              metalness 0
            }
            geometry Cylinder {
              height 0.03
              radius 0.075
            }
          }
        ]
        name "wheel_right"
        boundingObject USE WHEEL
        physics DEF WHEEL_PH Physics {
        }
      }
    }
    HingeJoint {
      jointParameters HingeJointParameters {
        anchor -0.27 0 0
      }
      device [
        RotationalMotor {
          name "motor_left"
        }
      ]
      endPoint Solid {
        translation -0.27 0 0
        rotation 0 -0.9999999999999999 0 1.5707953071795862
        children [
          USE WHEEL
        ]
        name "wheel_left"
        boundingObject USE WHEEL
        physics USE WHEEL_PH
      }
    }
    Pose {
      children [
        DEF bodemplaat Group {
          children [
            DEF hoek_onder_3l Pose {
              translation -0.199 0.292 0
              rotation 0 0 1 -0.9412
              children [
                Shape {
                  appearance PBRAppearance {
                    baseColor 0 0 0
                    metalness 0
                  }
                  geometry Box {
                    size 0.08 0.08 0.07
                  }
                }
              ]
            }
            DEF hoek_onder_3r Pose {
              translation 0.199 0.292 0
              rotation 0 0 -1 -0.9412
              children [
                Shape {
                  appearance PBRAppearance {
                    baseColor 0 0 0
                    metalness 0
                  }
                  geometry Box {
                    size 0.08 0.08 0.07
                  }
                }
              ]
            }
            DEF hoek_onder_2l Pose {
              translation -0.122836 -0.326363 0
              rotation 0 0 -1 0.35045
              children [
                Shape {
                  appearance PBRAppearance {
                    baseColor 0 0 0
                    metalness 0
                  }
                  geometry Box {
                    size 0.2 0.07 0.07
                  }
                }
              ]
            }
            DEF hoek_onder_2r Pose {
              translation 0.122836 -0.326363 0
              rotation 0 0 1 0.35045
              children [
                Shape {
                  appearance PBRAppearance {
                    baseColor 0 0 0
                    metalness 0
                  }
                  geometry Box {
                    size 0.2 0.07 0.07
                  }
                }
              ]
            }
            DEF hoek_onder_1r Pose {
              translation -0.2286 -0.29829 0
              rotation 0 0 1 -0.741073
              children [
                Shape {
                  appearance PBRAppearance {
                    baseColor 0 0 0
                    metalness 0
                  }
                  geometry Box {
                    size 0.038 0.038 0.07
                  }
                }
              ]
            }
            DEF hoek_onder_1l Pose {
              translation 0.2288 -0.29884 0
              rotation 0 0 1 -0.81107
              children [
                Shape {
                  appearance PBRAppearance {
                    baseColor 0 0 0
                    metalness 0
                  }
                  geometry Box {
                    size 0.038 0.038 0.07
                  }
                }
              ]
            }
            DEF middenstuk_onder_a Pose {
              translation 0 0.025 0
              children [
                Shape {
                  appearance PBRAppearance {
                    baseColor 0 0 0
                    metalness 0
                  }
                  geometry Box {
                    size 0.38 0.645 0.07
                  }
                }
              ]
            }
            DEF middenstuk_onder_b Pose {
              children [
                Shape {
                  appearance PBRAppearance {
                    baseColor 0 0 0
                    metalness 0
                  }
                  geometry Box {
                    size 0.51 0.6 0.07
                  }
                }
              ]
            }
            DEF middenstuk_onder_c Pose {
              translation 0 -0.015 0
              children [
                Shape {
                  appearance PBRAppearance {
                    baseColor 0 0 0
                    metalness 0
                  }
                  geometry Box {
                    size 0.455 0.62 0.07
                  }
                }
              ]
            }
            DEF middenstuk_onder_d Pose {
              translation 0 -0.023 0
              children [
                Shape {
                  appearance PBRAppearance {
                    baseColor 0 0 0
                    metalness 0
                  }
                  geometry Box {
                    size 0.08 0.74 0.07
                  }
                }
              ]
            }
          ]
        }
      ]
    }
    Pose {
      translation 0 0 0.192
      children [
        DEF bovenplaat Group {
          children [
            DEF hoek_boven_3l Pose {
              translation -0.199 0.292 0
              rotation 0 0 1 -0.9412
              children [
                Shape {
                  appearance PBRAppearance {
                    metalness 0
                  }
                  geometry Box {
                    size 0.08 0.08 0.18
                  }
                }
              ]
            }
            DEF hoek_boven_3r Pose {
              translation 0.199 0.292 0
              rotation 0 0 -1 -0.9412
              children [
                Shape {
                  appearance PBRAppearance {
                    metalness 0
                  }
                  geometry Box {
                    size 0.08 0.08 0.18
                  }
                }
              ]
            }
            DEF hoek_boven_2l Pose {
              translation -0.122836 -0.326363 0
              rotation 0 0 -1 0.35045
              children [
                Shape {
                  appearance PBRAppearance {
                    metalness 0
                  }
                  geometry Box {
                    size 0.2 0.07 0.18
                  }
                }
              ]
            }
            DEF hoek_boven_2r Pose {
              translation 0.122836 -0.326363 0
              rotation 0 0 1 0.35045
              children [
                Shape {
                  appearance PBRAppearance {
                    metalness 0
                  }
                  geometry Box {
                    size 0.2 0.07 0.18
                  }
                }
              ]
            }
            DEF hoek_boven_1r Pose {
              translation -0.2286 -0.29829 0
              rotation 0 0 1 -0.741073
              children [
                Shape {
                  appearance PBRAppearance {
                    metalness 0
                  }
                  geometry Box {
                    size 0.038 0.038 0.18
                  }
                }
              ]
            }
            DEF hoek_boven_1l Pose {
              translation 0.2288 -0.29884 0
              rotation 0 0 1 -0.81107
              children [
                Shape {
                  appearance PBRAppearance {
                    metalness 0
                  }
                  geometry Box {
                    size 0.038 0.038 0.18
                  }
                }
              ]
            }
            DEF middenstuk_boven_a Pose {
              translation 0 0.025 0
              children [
                Shape {
                  appearance PBRAppearance {
                    metalness 0
                  }
                  geometry Box {
                    size 0.38 0.645 0.18
                  }
                }
              ]
            }
            DEF middenstuk_boven_b Pose {
              children [
                Shape {
                  appearance PBRAppearance {
                    metalness 0
                  }
                  geometry Box {
                    size 0.51 0.6 0.18
                  }
                }
              ]
            }
            DEF middenstuk_boven_c Pose {
              translation 0 -0.015 0
              children [
                Shape {
                  appearance PBRAppearance {
                    metalness 0
                  }
                  geometry Box {
                    size 0.455 0.62 0.18
                  }
                }
              ]
            }
            DEF middenstuk_boven_d Pose {
              translation 0 -0.023 0
              children [
                Shape {
                  appearance PBRAppearance {
                    metalness 0
                  }
                  geometry Box {
                    size 0.08 0.74 0.18
                  }
                }
              ]
            }
          ]
        }
      ]
    }
  ]
  name "AGV"
  model "proANT436"
  boundingObject USE bodemplaat
  physics Physics {
    mass 1
  }
  controller "agv_controller"
}
