#VRML_SIM R2023b utf8

EXTERNPROTO "https://raw.githubusercontent.com/cyberbotics/webots/R2023b/projects/objects/backgrounds/protos/TexturedBackground.proto"
EXTERNPROTO "https://raw.githubusercontent.com/cyberbotics/webots/R2023b/projects/objects/backgrounds/protos/TexturedBackgroundLight.proto"
EXTERNPROTO "https://raw.githubusercontent.com/cyberbotics/webots/R2023b/projects/objects/floors/protos/RectangleArena.proto"

WorldInfo {
}
Viewpoint {
  orientation -0.18305957592110272 0.629741637440172 0.7549269247667333 0.7351325746042572
  position -2.460481825555911 -1.5537224937527228 1.4908253756581487
}
TexturedBackground {
}
TexturedBackgroundLight {
}
RectangleArena {
  floorSize 5 5
}
Robot {
  children [
    DEF BODY Shape {
        appearance PBRAppearance {
          baseColor 0.5 0.5 1
          metalness 0
        }
        geometry Cylinder {
          height 0.082
          radius 0.35
        }
    }
    HingeJoint {
      jointParameters HingeJointParameters {
        axis 0 1 0
        anchor 0.2 0 0
      }
      device [
        RotationalMotor {
          name "wheel_right"
        }
      ]
      endPoint Solid {
        translation 0.2 0 0
        rotation 0 1 0 1.5707996938995747
        children [
          DEF WHEEL_BIG Shape {
            appearance PBRAppearance {
              baseColor 0.5 0.5 1
              metalness 0
            }
            geometry Cylinder {
              height 0.07
              radius 0.07
            }
          }
        ]
        name " wheel_right"
        boundingObject USE WHEEL_BIG
      }
    }
    HingeJoint {
      jointParameters HingeJointParameters {
        axis 0 1 0
        anchor -0.2 0 0
      }
      device [
        RotationalMotor {
          name "wheel_left"
        }
      ]
      endPoint Solid {
        translation -0.2 0 0
        rotation 0 1 0 1.5707996938995747
        children [
          USE WHEEL_BIG
        ]
        name "wheel_left"
        boundingObject DEF WHEEL_BIG Shape {
          appearance PBRAppearance {
            baseColor 0.5 0.5 1
            metalness 0
          }
          geometry Cylinder {
            height 0.07
            radius 0.07
          }
        }
      }
    }
    HingeJoint {
      jointParameters HingeJointParameters {
        axis 0 1 0
        anchor 0 0.2 0
      }
      device [
        RotationalMotor {
          name "wheel_front"
        }
      ]
      endPoint Solid {
        translation 0 0.2 0
        rotation 0 1 0 1.5707996938995747
        children [
          DEF WHEEL_SMALL Shape {
            appearance PBRAppearance {
              baseColor 0.5 0.5 1
              metalness 0
            }
            geometry Cylinder {
              height 0.07
              radius 0.07
            }
          }
        ]
        name "wheel_front"
        boundingObject USE WHEEL_SMALL
      }
    }
  ]
  name "Rony de robotstofzuiger"
  model "Mijia G1"
  boundingObject USE BODY
  physics Physics {
  }
}
