#VRML_SIM R2023b utf8

EXTERNPROTO "https://raw.githubusercontent.com/cyberbotics/webots/R2023b/projects/objects/backgrounds/protos/TexturedBackground.proto"
EXTERNPROTO "https://raw.githubusercontent.com/cyberbotics/webots/R2023b/projects/objects/backgrounds/protos/TexturedBackgroundLight.proto"
EXTERNPROTO "https://raw.githubusercontent.com/cyberbotics/webots/R2023b/projects/objects/floors/protos/RectangleArena.proto"
EXTERNPROTO "https://raw.githubusercontent.com/cyberbotics/webots/R2023b/projects/robots/gctronic/elisa/protos/Elisa3.proto"
EXTERNPROTO "https://raw.githubusercontent.com/cyberbotics/webots/R2023b/projects/objects/factory/containers/protos/WoodenBox.proto"

WorldInfo {
}
Viewpoint {
  orientation -0.46704667112958403 0.4641375160731933 0.7526245897924013 1.8572402361645675
  position -0.1250955550431148 -0.4672466643171236 0.43030409293613425
}
TexturedBackground {
}
TexturedBackgroundLight {
}
RectangleArena {
}
Elisa3 {
  translation -0.225366 -0.315187 0
  rotation 0 0 1 0.261799
  controller "Elisa_bumper"
  extensionSlot [
    DEF NEEDLE HingeJoint {
      jointParameters HingeJointParameters {
        axis 0 0 1
      }
      device [
        RotationalMotor {
          name "arrow"
        }
      ]
      endPoint Solid {
        translation 1.03647e-08 0.01 0.03
        rotation -0.5773489358556708 0.5773509358554485 0.5773509358554485 2.094395307179586
        children [
          Shape {
            appearance PBRAppearance {
              baseColor 1 0 0
              metalness 0
            }
            geometry Cone {
              bottomRadius 0.003
              height 0.06
            }
          }
          DEF NEEDLE_BODY Pose {
          }
        ]
        name "solid(1)"
      }
    }
    Compass {
    }
    TouchSensor {
      translation 0.03 0 0.01
      children [
        DEF BUMPER Shape {
          appearance PBRAppearance {
          }
          geometry Box {
            size 0.001 0.02 0.001
          }
        }
      ]
      boundingObject USE BUMPER
    }
  ]
}
WoodenBox {
  translation -0.233823 0.135 0.05
  rotation 0 0 1 -0.523595307179586
  name "wooden box 1"
  size 0.1 0.1 0.1
}
WoodenBox {
  translation -0.0732373 -0.282427 0.05
  rotation 0 0 1 -1.3089953071795861
  name "wooden box 2"
  size 0.1 0.1 0.1
}
WoodenBox {
  translation 0.241866 0.16434 0.05
  rotation 0 0 1 -1.3089953071795861
  name "wooden box 3"
  size 0.1 0.1 0.1
}
